<?xml version='1.0'?>
<robot name="carpole" xmlns:xacro="http://www.ros.org/wiki/xacro">
  <xacro:include filename="$(find carpole)/urdf/carpole.gazebo" />
  <link name="world"/>

  <link name="base_rail">
    <collision>
      <origin xyz="0 0 0" rpy="0 0 0"/>
      <geometry>
        <box size="2.0 0.04 0.04"/>
      </geometry>
    </collision>

    <visual>
      <origin xyz="0 0 0" rpy="0 0 0"/>
      <geometry>
        <box size="2.0 0.04 0.04"/>
      </geometry>
      <material name="orange"/>
    </visual>

    <inertial>
      <origin xyz="0 0 0" rpy="0 0 0"/>
      <mass value="1"/>
      <inertia
        ixx="1.0" ixy="0.0" ixz="0.0"
        iyy="1.0" iyz="0.0"
        izz="1.0"/>
    </inertial>
  </link>


  <link name="car">
    <collision>
      <origin xyz="0 0 0" rpy="0 0 0"/>
      <geometry>
        <box size="0.08 0.08 0.05"/>
      </geometry>
    </collision>

    <visual>
      <origin xyz="0 0 0" rpy="0 0 0"/>
      <geometry>
        <box size="0.08 0.08 0.05"/>
      </geometry>
    </visual>

    <inertial>
      <origin xyz="0 0 0" rpy="0 0 0"/>
      <mass value="1.0"/>
      <inertia
        ixx="0.1" ixy="0.0" ixz="0.0"
        iyy="0.1" iyz="0.0"
        izz="0.1"/>
    </inertial>
  </link>


  <link name="bar">
    <collision>
      <origin xyz="0.3 -0.005 0" rpy="0 0 0"/>
      <geometry>
        <box size="0.6 0.01 0.01"/>
      </geometry>
    </collision>

    <visual>
      <origin xyz="0.3 -0.005 0" rpy="0 0 0"/>
      <geometry>
        <box size="0.6 0.01 0.01"/>
      </geometry>
    </visual>

    <inertial>
      <origin xyz="0.3 -0.005 0" rpy="0 0 0"/>
      <mass value="0.001"/>
      <inertia
        ixx="0.001" ixy="0.0" ixz="0.0"
        iyy="0.001" iyz="0.0"
        izz="0.001"/>
    </inertial>
  </link>


  <link name="masspoint">
    <collision>
      <origin xyz="0 0 0" rpy="0 0 0"/>
      <geometry>
        <box size="0.02 0.02 0.02"/>
      </geometry>
    </collision>

    <visual>
      <origin xyz="0 0 0" rpy="0 0 0"/>
      <geometry>
        <box size="0.02 0.02 0.02"/>
      </geometry>
    </visual>

    <inertial>
      <origin xyz="0 0 0" rpy="0 0 0"/>
      <mass value="3.0"/>
      <inertia
        ixx="0.1" ixy="0" ixz="0"
        iyy="0.1" iyz="0"
        izz="0.1"/>
    </inertial>
  </link>

  <joint name="fixedjoint" type="fixed">
    <parent link="world"/>
    <child link="base_rail"/>
    <origin xyz="0 0 1" rpy="0 0 0"/>
  </joint>

  <joint name="carsld" type="prismatic">
    <parent link="base_rail"/>
    <child link="car"/>
    <origin xyz="0 0 0.045" rpy="0 0 0"/>
    <axis xyz="1 0 0"/>
    <limit lower="-1"
         upper="1"
         effort="1000.0"
         velocity="1005.0" />
  </joint>

  <joint name="bar_car" type="continuous">
    <parent link="car"/>
    <child link="bar"/>
    <origin xyz="0 -0.04 0" rpy="0 0 0"/>
    <axis xyz="0 1 0"/>
    <!-- <hardwareInterface>hardware_interface/EffortJointInterface</hardwareInterface> -->
    <!-- <anchor xyz="0 0 0"/> -->
  </joint>

  <joint name="bar_mass" type="fixed">
    <parent link="bar"/>
    <child link="masspoint"/>
    <origin xyz="0.6 -0.005 0" rpy="0 0 0"/>
  </joint>

  <transmission name="linear_rail">
    <type>transmission_interface/SimpleTransmission</type>
    <joint name="carsld">
      <hardwareInterface>hardware_interface/EffortJointInterface</hardwareInterface>
    </joint>
    <actuator name="motor1">
      <hardwareInterface>hardware_interface/EffortJointInterface</hardwareInterface>
      <mechanicalReduction>1</mechanicalReduction>
    </actuator>
  </transmission>

  <transmission name="bar_car">
    <type>transmission_interface/SimpleTransmission</type>
    <joint name="bar_car">
      <hardwareInterface>hardware_interface/EffortJointInterface</hardwareInterface>
    </joint>
    <actuator name="motor2">
      <hardwareInterface>hardware_interface/EffortJointInterface</hardwareInterface>
      <mechanicalReduction>1</mechanicalReduction>
    </actuator>
  </transmission>



</robot>
